Workbook

Sheet DATABASED 
A1: booking_id | B1: flight_date | C1: route | D1: airline | E1: ticket_price | F1: baggage_add_on | G1: baggage_fee | H1: issued_error | I1: payment_method
A2: 1001 | B2: 45658 | C2: DPS-SIN | D2: Lion Air | E2: 2129626 | F2: 0 | G2: 0 | H2: Yes | I2: Credit Card
A3: 1002 | B3: 45689 | C3: CGK-KUL | D3: Citilink | E3: 1511774 | F3: 1 | G3: 250000 | H3: No | I3: Credit Card
A4: 1003 | B4: 45717 | C4: CGK-SUB | D4: Garuda | E4: 2441093 | F4: 1 | G4: 200000 | H4: Yes | I4: E-Wallet
A5: 1004 | B5: 45748 | C5: CGK-KUL | D5: AirAsia | E5: 1161079 | F5: 1 | G5: 150000 | H5: No | I5: Transfer
A6: 1005 | B6: 45778 | C6: CGK-KUL | D6: AirAsia | E6: 1068452 | F6: 1 | G6: 150000 | H6: No | I6: Credit Card
A7: 1006 | B7: 45809 | C7: CGK-SIN | D7: Citilink | E7: 806081 | F7: 1 | G7: 200000 | H7: No | I7: Credit Card
A8: 1007 | B8: 45839 | C8: CGK-SUB | D8: AirAsia | E8: 1683237 | F8: 1 | G8: 150000 | H8: No | I8: E-Wallet
A9: 1008 | B9: 45870 | C9: CGK-SUB | D9: Garuda | E9: 2361909 | F9: 0 | G9: 0 | H9: No | I9: Credit Card
A10: 1009 | B10: 45901 | C10: CGK-SUB | D10: Citilink | E10: 1258986 | F10: 1 | G10: 0 | H10: No | I10: Transfer
A11: 1010 | B11: 45931 | C11: CGK-KUL | D11: Garuda | E11: 810078 | F11: 0 | G11: 0 | H11: No | I11: E-Wallet
A12: 1011 | B12: 45962 | C12: DPS-SIN | D12: Citilink | E12: 722671 | F12: 0 | G12: 0 | H12: No | I12: Credit Card
A13: 1012 | B13: 45992 | C13: CGK-SUB | D13: Citilink | E13: 2166976 | F13: 1 | G13: 0 | H13: No | I13: E-Wallet
A14: 1013 | B14: 13/01/2025 | C14: CGK-KUL | D14: Lion Air | E14: 2104104 | F14: 0 | G14: 0 | H14: No | I14: Credit Card
A15: 1014 | B15: 14/01/2025 | C15: CGK-SIN | D15: Garuda | E15: 2359066 | F15: 1 | G15: 250000 | H15: No | I15: Credit Card
A16: 1015 | B16: 15/01/2025 | C16: DPS-SIN | D16: AirAsia | E16: 751663 | F16: 1 | G16: 250000 | H16: No | I16: Credit Card
A17: 1016 | B17: 16/01/2025 | C17: CGK-SIN | D17: AirAsia | E17: 1764284 | F17: 1 | G17: 250000 | H17: Yes | I17: Transfer
A18: 1017 | B18: 17/01/2025 | C18: DPS-SIN | D18: Garuda | E18: 1011955 | F18: 0 | G18: 0 | H18: No | I18: Transfer
A19: 1018 | B19: 18/01/2025 | C19: CGK-KUL | D19: AirAsia | E19: 1882459 | F19: 0 | G19: 0 | H19: Yes | I19: E-Wallet
A20: 1019 | B20: 19/01/2025 | C20: CGK-DPS | D20: AirAsia | E20: 2066970 | F20: 1 | G20: 0 | H20: No | I20: Credit Card
A21: 1020 | B21: 20/01/2025 | C21: DPS-SIN | D21: Garuda | E21: 812547 | F21: 1 | G21: 250000 | H21: No | I21: Credit Card
A22: 1021 | B22: 21/01/2025 | C22: CGK-SIN | D22: Citilink | E22: 1610681 | F22: 1 | G22: 250000 | H22: No | I22: Transfer
A23: 1022 | B23: 22/01/2025 | C23: CGK-KUL | D23: Garuda | E23: 2307618 | F23: 1 | G23: 250000 | H23: No | I23: Credit Card
A24: 1023 | B24: 23/01/2025 | C24: DPS-SIN | D24: Citilink | E24: 2499678 | F24: 1 | G24: 200000 | H24: No | I24: Transfer
A25: 1024 | B25: 24/01/2025 | C25: CGK-DPS | D25: AirAsia | E25: 842483 | F25: 0 | G25: 0 | H25: No | I25: Credit Card
... A32: 1031 | B32: 31/01/2025 | C32: CGK-SUB | D32: Garuda | E32: 1443974 | F32: 1 | G32: 0 | H32: No | I32: Transfer
A33: 1032 | B33: 45659 | C33: DPS-SIN | D33: Lion Air | E33: 1587121 | F33: 1 | G33: 0 | H33: No | I33: E-Wallet
A34: 1033 | B34: 45690 | C34: DPS-SIN | D34: Garuda | E34: 2021831 | F34: 0 | G34: 0 | H34: Yes | I34: E-Wallet
A35: 1034 | B35: 45718 | C35: CGK-DPS | D35: Garuda | E35: 2048224 | F35: 1 | G35: 200000 | H35: Yes | I35: Transfer
A36: 1035 | B36: 45749 | C36: CGK-SUB | D36: Lion Air | E36: 2405738 | F36: 1 | G36: 0 | H36: No | I36: Transfer
A37: 1036 | B37: 45779 | C37: CGK-KUL | D37: Citilink | E37: 1756731 | F37: 0 | G37: 0 | H37: No | I37: Transfer
A38: 1037 | B38: 45810 | C38: CGK-SUB | D38: Citilink | E38: 2215448 | F38: 1 | G38: 200000 | H38: No | I38: Transfer
A39: 1038 | B39: 45840 | C39: CGK-KUL | D39: Citilink | E39: 1525816 | F39: 1 | G39: 0 | H39: No | I39: Transfer
A40: 1039 | B40: 45871 | C40: CGK-DPS | D40: Citilink | E40: 1074705 | F40: 1 | G40: 0 | H40: No | I40: E-Wallet
A41: 1040 | B41: 45902 | C41: CGK-SIN | D41: Citilink | E41: 2320118 | F41: 1 | G41: 250000 | H41: No | I41: E-Wallet
A42: 1041 | B42: 45932 | C42: DPS-SIN | D42: Lion Air | E42: 2358845 | F42: 1 | G42: 150000 | H42: No | I42: Transfer
A43: 1042 | B43: 45963 | C43: CGK-DPS | D43: Lion Air | E43: 1254594 | F43: 0 | G43: 0 | H43: No | I43: Credit Card
A44: 1043 | B44: 45993 | C44: DPS-SIN | D44: AirAsia | E44: 847718 | F44: 0 | G44: 0 | H44: Yes | I44: Transfer
A45: 1044 | B45: 13/02/2025 | C45: CGK-SIN | D45: Citilink | E45: 2057563 | F45: 1 | G45: 0 | H45: No | I45: Credit Card
A46: 1045 | B46: 14/02/2025 | C46: CGK-SIN | D46: Lion Air | E46: 1345263 | F46: 1 | G46: 0 | H46: No | I46: Transfer
...

Sheet STEP BY STEP
A2: 1. Change flight date format to date with =DATEVALUE(B2); if there's error. 🔧 Fix Locale File → Settings Region → Indonesia Save & reload reload=DATEVALUE(B2)
A4: 2. Change ticket and baggage price with currency format
A5: 3. make sure if the baggage is 0 fee also 0 (using filter)
A6: 4. create new colom for total revenue (fligth ticket and baggage)
A7: 5. create new colom untuk error flight, fungsinya untuk menghitung berapa jumlag error yang ada
A9: 6. Pivot 1 — Revenue Bagasi per Rute
A10: 7. Pivot 2 — Error Rate per Maskapai
A11: 8. Pivot 3 — Transaksi Bagasi

Sheet CLEAN DATA
A1: booking_id | B1: flight_date | C1: route | D1: airline | E1: ticket_price | F1: baggage_add_on | G1: baggage_fee | H1: issued_error | I1: payment_method | J1: total revenue | K1: error flag
A2: 1001 | B2: =DATEVALUE('DATABASED '!B2) -> 45658 | C2: DPS-SIN | D2: Lion Air | E2: 2129626 | F2: 0 | G2: 0 | H2: Yes | I2: Credit Card | J2: =E2+G2 -> 2129626 | K2: =IF(H2="YES",1,0) -> 1
A3: 1002 | B3: =DATEVALUE('DATABASED '!B3) -> 45659 | C3: CGK-KUL | D3: Citilink | E3: 1511774 | F3: 1 | G3: 250000 | H3: No | I3: Credit Card | J3: =E3+G3 -> 1761774 | K3: =IF(H3="YES",1,0) -> 0
A4: 1003 | B4: =DATEVALUE('DATABASED '!B4) -> 45660 | C4: CGK-SUB | D4: Garuda | E4: 2441093 | F4: 1 | G4: 200000 | H4: Yes | I4: E-Wallet | J4: =E4+G4 -> 2641093 | K4: =IF(H4="YES",1,0) -> 1
A5: 1004 | B5: =DATEVALUE('DATABASED '!B5) -> 45661 | C5: CGK-KUL | D5: AirAsia | E5: 1161079 | F5: 1 | G5: 150000 | H5: No | I5: Transfer | J5: =E5+G5 -> 1311079 | K5: =IF(H5="YES",1,0) -> 0
A6: 1005 | B6: =DATEVALUE('DATABASED '!B6) -> 45662 | C6: CGK-KUL | D6: AirAsia | E6: 1068452 | F6: 1 | G6: 150000 | H6: No | I6: Credit Card | J6: =E6+G6 -> 1218452 | K6: =IF(H6="YES",1,0) -> 0
A7: 1006 | B7: =DATEVALUE('DATABASED '!B7) -> 45663 | C7: CGK-SIN | D7: Citilink | E7: 806081 | F7: 1 | G7: 200000 | H7: No | I7: Credit Card | J7: =E7+G7 -> 1006081 | K7: =IF(H7="YES",1,0) -> 0
A8: 1007 | B8: =DATEVALUE('DATABASED '!B8) -> 45664 | C8: CGK-SUB | D8: AirAsia | E8: 1683237 | F8: 1 | G8: 150000 | H8: No | I8: E-Wallet | J8: =E8+G8 -> 1833237 | K8: =IF(H8="YES",1,0) -> 0
A9: 1008 | B9: =DATEVALUE('DATABASED '!B9) -> 45665 | C9: CGK-SUB | D9: Garuda | E9: 2361909 | F9: 0 | G9: 0 | H9: No | I9: Credit Card | J9: =E9+G9 -> 2361909 | K9: =IF(H9="YES",1,0) -> 0
A10: 1009 | B10: =DATEVALUE('DATABASED '!B10) -> 45666 | C10: CGK-SUB | D10: Citilink | E10: 1258986 | F10: 1 | G10: 0 | H10: No | I10: Transfer | J10: =E10+G10 -> 1258986 | K10: =IF(H10="YES",1,0) -> 0
A11: 1010 | B11: =DATEVALUE('DATABASED '!B11) -> 45667 | C11: CGK-KUL | D11: Garuda | E11: 810078 | F11: 0 | G11: 0 | H11: No | I11: E-Wallet | J11: =E11+G11 -> 810078 | K11: =IF(H11="YES",1,0) -> 0
A12: 1011 | B12: =DATEVALUE('DATABASED '!B12) -> 45668 | C12: DPS-SIN | D12: Citilink | E12: 722671 | F12: 0 | G12: 0 | H12: No | I12: Credit Card | J12: =E12+G12 -> 722671 | K12: =IF(H12="YES",1,0) -> 0
A13: 1012 | B13: =DATEVALUE('DATABASED '!B13) -> 45669 | C13: CGK-SUB | D13: Citilink | E13: 2166976 | F13: 1 | G13: 0 | H13: No | I13: E-Wallet | J13: =E13+G13 -> 2166976 | K13: =IF(H13="YES",1,0) -> 0
... A121: 1120 | B121: =DATEVALUE('DATABASED '!B121) -> 45777 | C121: CGK-SIN | D121: Citilink | E121: 2320197 | F121: 1 | G121: 250000 | H121: No | I121: Credit Card | J121: =E121+G121 -> 2570197 | K121: =IF(H121="YES",1,0) -> 0
K127: Insight 1
K128: Rute CGK-SIN memiliki pendapatan bagasi tertinggi sebesar Rp2.550.000.
K130: Insight 2
K131: Maskapai Lion Air memiliki tingkat error issued tertinggi sebesar 25,93%.
K133: Insight 3 (Rekomendasi)
K134: Perlu dilakukan pengecekan tambahan pada rute DPS-SIN untuk mengurangi error dan meningkatkan revenue.karena rute tersebut memiliki volume transaksi tertinggi. Optimalisasi di rute ini berpotensi menurunkan error dan menjaga revenue bagasi.
A220: booking_id | B220: flight_date | C220: route | D220: airline | E220: ticket_price | F220: baggage_add_on | G220: baggage_fee | H220: issued_error
A221: 1002 | B221: 45659 | C221: DPS–SIN | D221: Lion Air | E221: 1,800,000 | F221: 1 | G221: 250 | H221: Yes
A222: 1015 | B222: 45672 | C222: DPS–SIN | D222: AirAsia | E222: 1,650,000 | F222: 1 | G222: 200 | H222: No
A223: 1038 | B223: 45695 | C223: CGK–SIN | D223: Garuda | E223: 2,100,000 | F223: 0 | G223: 0 | H223: No
A224: 1064 | B224: 45721 | C224: CGK–DPS | D224: Citilink | E224: 1,300,000 | F224: 1 | G224: 150 | H224: No
A225: 1091 | B225: 45748 | C225: CGK–KUL | D225: Lion Air | E225: 1,250,000 | F225: 0 | G225: 0 | H225: No

Sheet ANALYSIS
A1: ANALYSIS OF BAGGAGE POST ISSUEANCE
A5: 📊 Analysis 1 — Baggage Transaction by Route
A6: Pivot 1 — Revenue Bagasi per Rute
A15: Pivot analysis shows that DPS–SIN has the highest number of baggage add-on transactions compared to other routes.
A36: The analysis shows that DPS–SIN has the highest baggage add-on transaction volume. This route therefore represents a high-impact area where even small operational issues could result in significant revenue loss.
A39: 📊Analysis 2 — Issued Error by Analysis
A41: Pivot 2 — Error Rate per Maskapai
D42: %
D43: =C43/B43 -> 0.25925926
D44: =C44/B44 -> 0.14285714
D45: =C45/B45 -> 0.15625
D46: =C46/B46 -> 0.060606061
A62: When segmented by airline, Lion Air and Citilink show relatively high baggage transaction volumes across multiple routes. Airlines with consistently high baggage transaction volumes require closer monitoring, as operational errors on these airlines may have a broader financial impact
A64: 📊 Analysis 3 — Baggage Transaction Volume by Route
A66: Pivot 3 — Transaksi Bagasi
A75: Error analysis reveals that issuance errors occur move frequenlty on routes with higher transaction volume, particularly DPS-SIN
A96: Key Insights
A97: - DPS–SIN is the highest-volume route for baggage add-on transactions - Higher transaction volume is associated with a higher frequency of issuance errors - Routes contributing the most baggage revenue also carry the highest operational risk - Error monitoring should prioritize transaction volume rather than route count alone
A98: Recommendations
A99: - Prioritize additional quality control checks on DPS–SIN due to its high baggage transaction volume - Implement error monitoring dashboards for high-impact routes - Provide targeted refresher training for agents handling high-volume baggage issuance - Regularly review baggage issuance performance to reduce revenue leakage - Optimizing high-volume routes can help reduce issuance errors while protecting baggage revenue
A101: Conclusion
A102: By analyzing baggage revenue, transaction volume, and issued error patterns, this project highlights key operational focus areas where process improvements can deliver both efficiency gains and revenue protection.
A104: Tools Used
A105: - Microsoft Excel / Google Sheets - Pivot Tables - Data Visualization (Charts)

Sheet B
A1: booking_id | B1: flight_date | C1: route | D1: airline | E1: ticket_price | F1: baggage_add_on | G1: baggage_fee | H1: issued_error | I1: payment_method
A2: 1001 | B2: 45658 | C2: DPS-SIN | D2: Lion Air | E2: 2129626 | F2: 0 | G2: 0 | H2: Yes | I2: Credit Card
A3: 1002 | B3: 45689 | C3: CGK-KUL | D3: Citilink | E3: 1511774 | F3: 1 | G3: 250000 | H3: No | I3: Credit Card
A4: 1003 | B4: 45717 | C4: CGK-SUB | D4: Garuda | E4: 2441093 | F4: 1 | G4: 200000 | H4: Yes | I4: E-Wallet
A5: 1004 | B5: 45748 | C5: CGK-KUL | D5: AirAsia | E5: 1161079 | F5: 1 | G5: 150000 | H5: No | I5: Transfer
A6: 1005 | B6: 45778 | C6: CGK-KUL | D6: AirAsia | E6: 1068452 | F6: 1 | G6: 150000 | H6: No | I6: Credit Card
A7: 1006 | B7: 45809 | C7: CGK-SIN | D7: Citilink | E7: 806081 | F7: 1 | G7: 200000 | H7: No | I7: Credit Card
A8: 1007 | B8: 45839 | C8: CGK-SUB | D8: AirAsia | E8: 1683237 | F8: 1 | G8: 150000 | H8: No | I8: E-Wallet
A9: 1008 | B9: 45870 | C9: CGK-SUB | D9: Garuda | E9: 2361909 | F9: 0 | G9: 0 | H9: No | I9: Credit Card
A10: 1009 | B10: 45901 | C10: CGK-SUB | D10: Citilink | E10: 1258986 | F10: 1 | G10: 0 | H10: No | I10: Transfer
A11: 1010 | B11: 45931 | C11: CGK-KUL | D11: Garuda | E11: 810078 | F11: 0 | G11: 0 | H11: No | I11: E-Wallet
A12: 1011 | B12: 45962 | C12: DPS-SIN | D12: Citilink | E12: 722671 | F12: 0 | G12: 0 | H12: No | I12: Credit Card
A13: 1012 | B13: 45992 | C13: CGK-SUB | D13: Citilink | E13: 2166976 | F13: 1 | G13: 0 | H13: No | I13: E-Wallet
A14: 1013 | B14: 13/01/2025 | C14: CGK-KUL | D14: Lion Air | E14: 2104104 | F14: 0 | G14: 0 | H14: No | I14: Credit Card
A15: 1014 | B15: 14/01/2025 | C15: CGK-SIN | D15: Garuda | E15: 2359066 | F15: 1 | G15: 250000 | H15: No | I15: Credit Card
A16: 1015 | B16: 15/01/2025 | C16: DPS-SIN | D16: AirAsia | E16: 751663 | F16: 1 | G16: 250000 | H16: No | I16: Credit Card
A17: 1016 | B17: 16/01/2025 | C17: CGK-SIN | D17: AirAsia | E17: 1764284 | F17: 1 | G17: 250000 | H17: Yes | I17: Transfer
A18: 1017 | B18: 17/01/2025 | C18: DPS-SIN | D18: Garuda | E18: 1011955 | F18: 0 | G18: 0 | H18: No | I18: Transfer
A19: 1018 | B19: 18/01/2025 | C19: CGK-KUL | D19: AirAsia | E19: 1882459 | F19: 0 | G19: 0 | H19: Yes | I19: E-Wallet
A20: 1019 | B20: 19/01/2025 | C20: CGK-DPS | D20: AirAsia | E20: 2066970 | F20: 1 | G20: 0 | H20: No | I20: Credit Card
A21: 1020 | B21: 20/01/2025 | C21: DPS-SIN | D21: Garuda | E21: 812547 | F21: 1 | G21: 250000 | H21: No | I21: Credit Card
A22: 1021 | B22: 21/01/2025 | C22: CGK-SIN | D22: Citilink | E22: 1610681 | F22: 1 | G22: 250000 | H22: No | I22: Transfer
A23: 1022 | B23: 22/01/2025 | C23: CGK-KUL | D23: Garuda | E23: 2307618 | F23: 1 | G23: 250000 | H23: No | I23: Credit Card
A24: 1023 | B24: 23/01/2025 | C24: DPS-SIN | D24: Citilink | E24: 2499678 | F24: 1 | G24: 200000 | H24: No | I24: Transfer
A25: 1024 | B25: 24/01/2025 | C25: CGK-DPS | D25: AirAsia | E25: 842483 | F25: 0 | G25: 0 | H25: No | I25: Credit Card
... A32: 1031 | B32: 31/01/2025 | C32: CGK-SUB | D32: Garuda | E32: 1443974 | F32: 1 | G32: 0 | H32: No | I32: Transfer
A33: 1032 | B33: 45659 | C33: DPS-SIN | D33: Lion Air | E33: 1587121 | F33: 1 | G33: 0 | H33: No | I33: E-Wallet
A34: 1033 | B34: 45690 | C34: DPS-SIN | D34: Garuda | E34: 2021831 | F34: 0 | G34: 0 | H34: Yes | I34: E-Wallet
A35: 1034 | B35: 45718 | C35: CGK-DPS | D35: Garuda | E35: 2048224 | F35: 1 | G35: 200000 | H35: Yes | I35: Transfer
A36: 1035 | B36: 45749 | C36: CGK-SUB | D36: Lion Air | E36: 2405738 | F36: 1 | G36: 0 | H36: No | I36: Transfer
A37: 1036 | B37: 45779 | C37: CGK-KUL | D37: Citilink | E37: 1756731 | F37: 0 | G37: 0 | H37: No | I37: Transfer
A38: 1037 | B38: 45810 | C38: CGK-SUB | D38: Citilink | E38: 2215448 | F38: 1 | G38: 200000 | H38: No | I38: Transfer
A39: 1038 | B39: 45840 | C39: CGK-KUL | D39: Citilink | E39: 1525816 | F39: 1 | G39: 0 | H39: No | I39: Transfer
A40: 1039 | B40: 45871 | C40: CGK-DPS | D40: Citilink | E40: 1074705 | F40: 1 | G40: 0 | H40: No | I40: E-Wallet
A41: 1040 | B41: 45902 | C41: CGK-SIN | D41: Citilink | E41: 2320118 | F41: 1 | G41: 250000 | H41: No | I41: E-Wallet
A42: 1041 | B42: 45932 | C42: DPS-SIN | D42: Lion Air | E42: 2358845 | F42: 1 | G42: 150000 | H42: No | I42: Transfer
A43: 1042 | B43: 45963 | C43: CGK-DPS | D43: Lion Air | E43: 1254594 | F43: 0 | G43: 0 | H43: No | I43: Credit Card
A44: 1043 | B44: 45993 | C44: DPS-SIN | D44: AirAsia | E44: 847718 | F44: 0 | G44: 0 | H44: Yes | I44: Transfer
A45: 1044 | B45: 13/02/2025 | C45: CGK-SIN | D45: Citilink | E45: 2057563 | F45: 1 | G45: 0 | H45: No | I45: Credit Card
A46: 1045 | B46: 14/02/2025 | C46: CGK-SIN | D46: Lion Air | E46: 1345263 | F46: 1 | G46: 0 | H46: No | I46: Transfer
...
